<robot name="pi_robot">


	<!-- * * * Link Definitions * * * -->
    <link name="world"/>

 	<link name="base_link">
        <collision>
            <origin xyz="0 0 0.0425" rpy="0 0 0"/>
            <geometry>
                <box size="0.32 0.26 0.085"/>
            </geometry>
        </collision>
		<visual>
		    <origin xyz="0 0 0.0425" rpy="0 0 0"/>
			<geometry>
				<box size="0.32 0.26 0.085"/>
			</geometry>
		</visual>
	</link>

 	<link name="base_laser">
 	    <inertial>
            <origin xyz="0 0 0" rpy="0 0 0"/>
            <mass value="0.5" />
            <inertia ixx="1.0" ixy="0.0" ixz="0.0" iyy="1.0" iyz="0.0" izz="1.0"/>
        </inertial>
        <collision>
            <origin xyz="0 0 0" rpy="0 0 0"/>
            <geometry>
                <cylinder radius="0.025" length="0.07"/>
            </geometry>
        </collision>
		<visual>
		    <origin xyz="0 0 0" rpy="0 0 0"/>
			<geometry>
				<cylinder radius="0.025" length="0.07"/>
			</geometry>
		</visual>
	</link>

	<link name="cpu_link">
	    <inertial>
            <origin xyz="0 0 0.035" rpy="0 0 0"/>
            <mass value="0.5" />
            <inertia ixx="1.0" ixy="0.0" ixz="0.0" iyy="1.0" iyz="0.0" izz="1.0"/>
        </inertial>
        <collision>
            <origin xyz="0 0 0.035" rpy="0 0 0"/>
            <geometry>
                <box size="0.19 0.19 0.07"/>
            </geometry>
        </collision>
		<visual>
		    <origin xyz="0 0 0.035" rpy="0 0 0"/>
			<geometry>
				<box size="0.19 0.19 0.07"/>
			</geometry>
		</visual>
	</link>

  	<link name="upper_base_link">
  	    <inertial>
            <origin xyz="0 0 0.05" rpy="0 0 0"/>
            <mass value="10.0" />
            <inertia ixx="1.0" ixy="0.0" ixz="0.0" iyy="1.0" iyz="0.0" izz="1.0"/>
        </inertial>
        <collision>
            <origin xyz="0 0 0.05" rpy="0 0 0"/>
            <geometry>
                <cylinder radius="0.085" length="0.10"/>
            </geometry>
        </collision>
		<visual>
			<origin xyz="0 0 0.05" rpy="0 0 0"/>
			<geometry>
				<cylinder radius="0.085" length="0.10"/>
			</geometry>
	   </visual>
	</link>

  	<link name="torso_link">
  	    <inertial>
            <origin xyz="0 0 0.12" rpy="0 0 0"/>
            <mass value="0.5" />
            <inertia ixx="1.0" ixy="0.0" ixz="0.0" iyy="1.0" iyz="0.0" izz="1.0"/>
        </inertial>
        <collision>
            <origin xyz="0 0 0.12" rpy="0 0 0"/>
            <geometry>
                <cylinder radius="0.05" length="0.24"/>
            </geometry>
        </collision>
		<visual>
			<origin xyz="0 0 0.12" rpy="0 0 0"/>
			<geometry>
				<cylinder radius="0.05" length="0.24"/>
			</geometry>
	   </visual>
	</link>

	<link name="head_pan_link">
	    <inertial>
            <origin xyz="0 0 0.0225" rpy="0 0 0"/>
            <mass value="0.5" />
            <inertia ixx="1.0" ixy="0.0" ixz="0.0" iyy="1.0" iyz="0.0" izz="1.0"/>
        </inertial>
        <collision>
            <origin xyz="0 0 0.0225" rpy="0 0 0"/>
            <geometry>
                <box size="0.05 0.045 0.045"/>
            </geometry>
        </collision>
		<visual>
			<origin xyz="0 0 0.0225" rpy="0 0 0"/>
			<geometry>
				<box size="0.05 0.045 0.045"/>
			</geometry>
	   </visual>
	</link>

	<link name="head_tilt_link">
	    <inertial>
            <origin xyz="0 0 0.02" rpy="0 0 0"/>
            <mass value="0.5" />
            <inertia ixx="1.0" ixy="0.0" ixz="0.0" iyy="1.0" iyz="0.0" izz="1.0"/>
        </inertial>
        <collision>
            <origin xyz="0 0 0.02" rpy="0 0 0"/>
            <geometry>
                <box size="0.03 0.038 0.04"/>
            </geometry>
        </collision>
		<visual>
			<origin xyz="0 0 0.02" rpy="0 0 0"/>
			<geometry>
				<box size="0.03 0.038 0.04"/>
			</geometry>
	   </visual>
	</link>

	<link name="neck_link">
	    <inertial>
            <origin xyz="0 0 0.021" rpy="0 0 0"/>
            <mass value="0.5" />
            <inertia ixx="1.0" ixy="0.0" ixz="0.0" iyy="1.0" iyz="0.0" izz="1.0"/>
        </inertial>
        <collision>
            <origin xyz="0 0 0.021" rpy="0 0 0"/>
            <geometry>
                <box size="0.03 0.05 0.042"/>
            </geometry>
        </collision>
		<visual>
			<origin xyz="0 0 0.021" rpy="0 0 0"/>
			<geometry>
				<box size="0.03 0.05 0.042"/>
			</geometry>
	   </visual>
	</link>

	<link name="head_link">
	    <inertial>
            <origin xyz="0 0 0.025" rpy="0 0 0"/>
            <mass value="0.5" />
            <inertia ixx="1.0" ixy="0.0" ixz="0.0" iyy="1.0" iyz="0.0" izz="1.0"/>
        </inertial>
        <collision>
            <origin xyz="0 0 0.025" rpy="0 0 0"/>
            <geometry>
                <box size="0.03 0.07 0.11"/>
            </geometry>
        </collision>
		<visual>
			<origin xyz="0 0 0.025" rpy="0 0 0"/>
			<geometry>
				<box size="0.03 0.07 0.11"/>
			</geometry>
	   </visual>
	</link>

	<link name="antenna_link">
	    <inertial>
            <origin xyz="0 0 0.035" rpy="0 0 0"/>
            <mass value="0.5" />
            <inertia ixx="1.0" ixy="0.0" ixz="0.0" iyy="1.0" iyz="0.0" izz="1.0"/>
        </inertial>
        <collision>
            <origin xyz="0 0 0.035" rpy="0 0 0"/>
            <geometry>
                <cylinder radius="0.002" length="0.05"/>
            </geometry>
        </collision>
		<visual>
			<origin xyz="0 0 0.035" rpy="0 0 0"/>
			<geometry>
				<cylinder radius="0.002" length="0.05"/>
			</geometry>
	   </visual>
	</link>

	<link name="left_shoulder_link">
	    <inertial>
            <origin xyz="0 0 0" rpy="0 0 0"/>
            <mass value="0.5" />
            <inertia ixx="1.0" ixy="0.0" ixz="0.0" iyy="1.0" iyz="0.0" izz="1.0"/>
        </inertial>
        <collision>
            <origin xyz="0 0 0" rpy="0 0 0"/>
            <geometry>
                <box size="0.025 0.015 0.05"/>
            </geometry>
        </collision>
		<visual>
			<origin xyz="0 0 0" rpy="0 0 0"/>
			<geometry>
				<box size="0.025 0.015 0.05"/>
			</geometry>
	   </visual>
	</link>

	<link name="right_shoulder_link">
	    <inertial>
            <origin xyz="0 0 0" rpy="0 0 0"/>
            <mass value="0.5" />
            <inertia ixx="1.0" ixy="0.0" ixz="0.0" iyy="1.0" iyz="0.0" izz="1.0"/>
        </inertial>
        <collision>
            <origin xyz="0 0 0" rpy="0 0 0"/>
            <geometry>
                <box size="0.025 0.015 0.05"/>
            </geometry>
        </collision>
		<visual>
			<origin xyz="0 0 0" rpy="0 0 0"/>
			<geometry>
				<box size="0.025 0.015 0.05"/>
			</geometry>
	   </visual>
	</link>

	<link name="left_shoulder_forward_link">
	    <inertial>
            <origin xyz="0 0 0" rpy="0 0 0"/>
            <mass value="0.5" />
            <inertia ixx="1.0" ixy="0.0" ixz="0.0" iyy="1.0" iyz="0.0" izz="1.0"/>
        </inertial>
        <collision>
            <origin xyz="0 0 0" rpy="0 0 0"/>
            <geometry>
                <box size="0.03 0.05 0.03"/>
            </geometry>
        </collision>
		<visual>
			<origin xyz="0 0 0" rpy="0 0 0"/>
			<geometry>
				<box size="0.03 0.05 0.03"/>
			</geometry>
	   </visual>
	</link>

	<link name="right_shoulder_forward_link">
	    <inertial>
            <origin xyz="0 0 0" rpy="0 0 0"/>
            <mass value="0.5" />
            <inertia ixx="1.0" ixy="0.0" ixz="0.0" iyy="1.0" iyz="0.0" izz="1.0"/>
        </inertial>
        <collision>
            <origin xyz="0 0 0" rpy="0 0 0"/>
            <geometry>
                <box size="0.03 0.05 0.03"/>
            </geometry>
        </collision>
		<visual>
			<origin xyz="0 0 0" rpy="0 0 0"/>
			<geometry>
				<box size="0.03 0.05 0.03"/>
			</geometry>
	   </visual>
	</link>

	<link name="left_shoulder_up_link">
	    <inertial>
            <origin xyz="0 0 0" rpy="1.57 0 0"/>
            <mass value="0.5" />
            <inertia ixx="1.0" ixy="0.0" ixz="0.0" iyy="1.0" iyz="0.0" izz="1.0"/>
        </inertial>
        <collision>
            <origin xyz="0 0 0" rpy="1.57 0 0"/>
            <geometry>
                <box size="0.03 0.05 0.03"/>
            </geometry>
        </collision>
		<visual>
			<origin xyz="0 0 0" rpy="1.57 0 0"/>
			<geometry>
				<box size="0.03 0.05 0.03"/>
			</geometry>
	   </visual>
	</link>

	<link name="right_shoulder_up_link">
	    <inertial>
            <origin xyz="0 0 0" rpy="1.57 0 0"/>
            <mass value="0.5" />
            <inertia ixx="1.0" ixy="0.0" ixz="0.0" iyy="1.0" iyz="0.0" izz="1.0"/>
        </inertial>
        <collision>
            <origin xyz="0 0 0" rpy="1.57 0 0"/>
            <geometry>
                <box size="0.03 0.05 0.03"/>
            </geometry>
        </collision>
		<visual>
			<origin xyz="0 0 0" rpy="1.57 0 0"/>
			<geometry>
				<box size="0.03 0.05 0.03"/>
			</geometry>
	   </visual>
	</link>

	<link name="left_upper_arm_link">
	    <inertial>
            <origin xyz="0 0 0" rpy="0 0 0"/>
            <mass value="0.5" />
            <inertia ixx="1.0" ixy="0.0" ixz="0.0" iyy="1.0" iyz="0.0" izz="1.0"/>
        </inertial>
        <collision>
            <origin xyz="0 0 0" rpy="0 0 0"/>
            <geometry>
                <cylinder radius="0.0075" length="0.05"/>
            </geometry>
        </collision>
		<visual>
			<origin xyz="0 0 0" rpy="0 0 0"/>
			<geometry>
				<cylinder radius="0.0075" length="0.05"/>
			</geometry>
	   </visual>
	</link>

	<link name="right_upper_arm_link">
	    <inertial>
            <origin xyz="0 0 0" rpy="0 0 0"/>
            <mass value="0.5" />
            <inertia ixx="1.0" ixy="0.0" ixz="0.0" iyy="1.0" iyz="0.0" izz="1.0"/>
        </inertial>
        <collision>
            <origin xyz="0 0 0" rpy="0 0 0"/>
            <geometry>
                <cylinder radius="0.0075" length="0.05"/>
            </geometry>
        </collision>
		<visual>
			<origin xyz="0 0 0" rpy="0 0 0"/>
			<geometry>
				<cylinder radius="0.0075" length="0.05"/>
			</geometry>
	   </visual>
	</link>

	<link name="left_elbow_link">
	    <inertial>
            <origin xyz="0 0 0" rpy="0 0 1.57"/>
            <mass value="0.5" />
            <inertia ixx="1.0" ixy="0.0" ixz="0.0" iyy="1.0" iyz="0.0" izz="1.0"/>
        </inertial>
        <collision>
            <origin xyz="0 0 0" rpy="0 0 1.57"/>
            <geometry>
                <box size="0.035 0.035 0.05"/>
            </geometry>
        </collision>
		<visual>
			<origin xyz="0 0 0" rpy="0 0 1.57"/>
			<geometry>
				<box size="0.035 0.035 0.05"/>
			</geometry>
	   </visual>
	</link>

	<link name="right_elbow_link">
	    <inertial>
            <origin xyz="0 0 0" rpy="0 0 1.57"/>
            <mass value="0.5" />
            <inertia ixx="1.0" ixy="0.0" ixz="0.0" iyy="1.0" iyz="0.0" izz="1.0"/>
        </inertial>
        <collision>
            <origin xyz="0 0 0" rpy="0 0 1.57"/>
            <geometry>
                <box size="0.035 0.035 0.05"/>
            </geometry>
        </collision>
		<visual>
			<origin xyz="0 0 0" rpy="0 0 1.57"/>
			<geometry>
				<box size="0.035 0.035 0.05"/>
			</geometry>
	   </visual>
	</link>

	<link name="left_lower_arm_link">
	    <inertial>
            <origin xyz="0 0 0" rpy="0 0 0"/>
            <mass value="0.5" />
            <inertia ixx="1.0" ixy="0.0" ixz="0.0" iyy="1.0" iyz="0.0" izz="1.0"/>
        </inertial>
        <collision>
            <origin xyz="0 0 0" rpy="0 0 0"/>
            <geometry>
                <cylinder radius="0.0075" length="0.11"/>
            </geometry>
        </collision>
		<visual>
			<origin xyz="0 0 0" rpy="0 0 0"/>
			<geometry>
				<cylinder radius="0.0075" length="0.11"/>
			</geometry>
	   </visual>
	</link>

	<link name="right_lower_arm_link">
	    <inertial>
            <origin xyz="0 0 0" rpy="0 0 0"/>
            <mass value="0.5" />
            <inertia ixx="1.0" ixy="0.0" ixz="0.0" iyy="1.0" iyz="0.0" izz="1.0"/>
        </inertial>
        <collision>
            <origin xyz="0 0 0" rpy="0 0 0"/>
            <geometry>
                <cylinder radius="0.0075" length="0.11"/>
            </geometry>
        </collision>
		<visual>
			<origin xyz="0 0 0" rpy="0 0 0"/>
			<geometry>
				<cylinder radius="0.0075" length="0.11"/>
			</geometry>
	   </visual>
	</link>

	<link name="left_wrist_link">
	    <inertial>
            <origin xyz="0 0 0" rpy="1.57 0 0"/>
            <mass value="0.5" />
            <inertia ixx="1.0" ixy="0.0" ixz="0.0" iyy="1.0" iyz="0.0" izz="1.0"/>
        </inertial>
        <collision>
            <origin xyz="0 0 0" rpy="1.57 0 0"/>
            <geometry>
                <box size="0.03 0.05 0.03"/>
            </geometry>
        </collision>
		<visual>
			<origin xyz="0 0 0" rpy="1.57 0 0"/>
			<geometry>
				<box size="0.03 0.05 0.03"/>
			</geometry>
	   </visual>
	</link>

	<link name="right_wrist_link">
	    <inertial>
            <origin xyz="0 0 0" rpy="1.57 0 0"/>
            <mass value="0.5" />
            <inertia ixx="1.0" ixy="0.0" ixz="0.0" iyy="1.0" iyz="0.0" izz="1.0"/>
        </inertial>
        <collision>
            <origin xyz="0 0 0" rpy="1.57 0 0"/>
            <geometry>
                <box size="0.03 0.05 0.03"/>
            </geometry>
        </collision>
		<visual>
			<origin xyz="0 0 0" rpy="1.57 0 0"/>
			<geometry>
				<box size="0.03 0.05 0.03"/>
			</geometry>
	   </visual>
	</link>

	<link name="left_hand_link">
	    <inertial>
            <origin xyz="0 0 0" rpy="0 0 0"/>
            <mass value="0.5" />
            <inertia ixx="1.0" ixy="0.0" ixz="0.0" iyy="1.0" iyz="0.0" izz="1.0"/>
        </inertial>
        <collision>
            <origin xyz="0 0 0" rpy="0 0 0"/>
            <geometry>
                <box size="0.03 0.01 0.06"/>
            </geometry>
        </collision>
		<visual>
			<origin xyz="0 0 0" rpy="0 0 0"/>
			<geometry>
				<box size="0.03 0.01 0.06"/>
			</geometry>
	   </visual>
	</link>

	<link name="right_hand_link">
	    <inertial>
            <origin xyz="0 0 0" rpy="0 0 0"/>
            <mass value="0.5" />
            <inertia ixx="1.0" ixy="0.0" ixz="0.0" iyy="1.0" iyz="0.0" izz="1.0"/>
        </inertial>
        <collision>
            <origin xyz="0 0 0" rpy="0 0 0"/>
            <geometry>
                <box size="0.03 0.01 0.06"/>
            </geometry>
        </collision>
		<visual>
			<origin xyz="0 0 0" rpy="0 0 0"/>
			<geometry>
				<box size="0.03 0.01 0.06"/>
			</geometry>
	   </visual>
	</link>

	<!-- * * * Joint Definitions * * * -->



    <joint name="fixed" type="fixed">
        <parent link="world"/>
        <child link="base_link"/>
    </joint>

	<joint name="cpu_joint" type="fixed">
    	<parent link="base_link"/>
    	<child link="cpu_link"/>
    	<origin xyz="0.025 0 0.085" rpy="0 0 0"/>
	</joint>

	<joint name="base_laser_joint" type="fixed">
    	<parent link="base_link"/>
    	<child link="base_laser"/>
    	<origin xyz="0.18 0 0.07" rpy="0 0 0"/>
	</joint>

	<joint name="upper_base_joint" type="fixed">
    	<parent link="cpu_link"/>
    	<child link="upper_base_link"/>
    	<origin xyz="0 0 0.07" rpy="0 0 0"/>
	</joint>
    <!--
	<joint name="torso_joint" type="revolute">
    	<parent link="upper_base_link"/>
    	<child link="torso_link"/>
    	<origin xyz="0 0 0.10" rpy="0 0 0"/>
    	<axis xyz="0 0 1"/>
    	<limit lower="-3.1416" upper="3.1416" effort="10" velocity="3"/>
  	</joint>
  	-->
  	<joint name="torso_joint" type="continuous">
    	<parent link="upper_base_link"/>
    	<child link="torso_link"/>
    	<origin xyz="0 0 0.10" rpy="0 0 0"/>
    	<axis xyz="0 0 1"/>
    	<dynamics damping="0.7"/>
  	</joint>

	<joint name="head_pan_servo" type="fixed">
    	<parent link="torso_link"/>
    	<child link="head_pan_link"/>
    	<origin xyz="0 0 0.225" rpy="0 0 0"/>
	</joint>
	<!--
	<joint name="head_pan_joint" type="revolute">
    	<parent link="head_pan_link"/>
    	<child link="head_tilt_link"/>
    	<origin xyz="0 0 0.045" rpy="0 0 0"/>
    	<axis xyz="0 0 1"/>
    	<limit lower="-3.1416" upper="3.1416" effort="10" velocity="3"/>
  	</joint>
  	-->
    <joint name="head_pan_joint" type="continuous">
        <parent link="head_pan_link"/>
        <child link="head_tilt_link"/>
        <origin xyz="0 0 0.045" rpy="0 0 0"/>
        <axis xyz="0 0 1"/>
        <dynamics damping="0.7"/>
    </joint>

 	<joint name="head_tilt_joint" type="revolute">
    	<parent link="head_tilt_link"/>
    	<child link="neck_link"/>
    	<origin xyz="0 0 0.04" rpy="0 0 0"/>
    	<axis xyz="0 1 0"/>
    	<limit lower="-1.57" upper="0.6" effort="10" velocity="3"/>
  	</joint>

    <!--
    <gazebo>
        <plugin name="gazebo_ros_control" filename="libgazebo_ros_control.so">
            <robotNamespace>/pi_robot</robotNamespace>
            <robotSimType>gazebo_ros_control/DefaultRobotHWSim</robotSimType>
        </plugin>
    </gazebo>




-->

 	<joint name="neck_joint" type="fixed">
    	<parent link="neck_link"/>
    	<child link="head_link"/>
    	<origin xyz="0.05 0 0.015" rpy="0 0 0"/>
	</joint>
<!--
	<joint name="eyes_joint" type="fixed">
    	<parent link="head_link" />
    	<child link="eyes_link" />
    	<origin xyz="0.02 0 0.03" rpy="0 0 0" />
	</joint>
-->

	<joint name="antenna_joint" type="fixed">
    	<parent link="head_link"/>
    	<child link="antenna_link"/>
    	<origin xyz="0.0 -0.025 0.065" rpy="0 0 0"/>
	</joint>

 	<joint name="left_shoulder_joint" type="fixed">
    	<parent link="torso_link"/>
    	<child link="left_shoulder_link"/>
    	<origin xyz="0 0.055 0.165" rpy="0 0 0"/>
	</joint>

 	<joint name="right_shoulder_joint" type="fixed">
    	<parent link="torso_link"/>
    	<child link="right_shoulder_link"/>
    	<origin xyz="0 -0.055 0.165" rpy="0 0 0"/>
	</joint>

 	<joint name="left_shoulder_forward_joint" type="revolute">
    	<parent link="left_shoulder_link"/>
    	<child link="left_shoulder_forward_link"/>
    	<origin xyz="0 0.025 0" rpy="0 0 0"/>
       	<limit lower="-1.57" upper="1.57" effort="10" velocity="3"/>
        <axis xyz="0 0 1"/>
	</joint>

 	<joint name="right_shoulder_forward_joint" type="revolute">
    	<parent link="right_shoulder_link"/>
    	<child link="right_shoulder_forward_link"/>
    	<origin xyz="0 -0.025 0" rpy="0 0 0"/>
       	<limit lower="-1.57" upper="1.57" effort="10" velocity="3"/>
        <axis xyz="0 0 1"/>
	</joint>

 	<joint name="left_shoulder_up_joint" type="revolute">
    	<parent link="left_shoulder_forward_link"/>
    	<child link="left_shoulder_up_link"/>
    	<origin xyz="0 0.04 -0.01" rpy="0 -0.707 0"/>
       	<limit lower="-1.57" upper="1.57" effort="10" velocity="3"/>
        <axis xyz="0 1 0"/>
	</joint>

 	<joint name="right_shoulder_up_joint" type="revolute">
    	<parent link="right_shoulder_forward_link"/>
    	<child link="right_shoulder_up_link"/>
    	<origin xyz="0 -0.04 -0.01" rpy="0 -0.707 0"/>
       	<limit lower="-1.57" upper="1.57" effort="10" velocity="3"/>
        <axis xyz="0 1 0"/>
	</joint>






 	<joint name="left_upper_arm_joint" type="fixed">
    	<parent link="left_shoulder_up_link"/>
    	<child link="left_upper_arm_link"/>
    	<origin xyz="0 0 -0.05" rpy="0 0 0"/>
	</joint>

 	<joint name="right_upper_arm_joint" type="fixed">
    	<parent link="right_shoulder_up_link"/>
    	<child link="right_upper_arm_link"/>
    	<origin xyz="0 0 -0.05" rpy="0 0 0"/>
	</joint>


 	<joint name="left_elbow_joint" type="revolute">
    	<parent link="left_upper_arm_link"/>
    	<child link="left_elbow_link"/>
    	<origin xyz="-0.005 0 -0.05" rpy="0 0 0"/>
       	<limit lower="-1.57" upper="1.57" effort="10" velocity="3"/>
        <axis xyz="0 1 0"/>
	</joint>
	<!--
	<joint name="left_elbow_joint" type="continuous">
        <parent link="left_upper_arm_link"/>
        <child link="left_elbow_link"/>
        <origin xyz="-0.005 0 -0.05" rpy="0 0 0"/>
        <axis xyz="0 0 1"/>
        <dynamics damping="0.7"/>
    </joint>
	-->

 	<joint name="right_elbow_joint" type="revolute">
    	<parent link="right_upper_arm_link"/>
    	<child link="right_elbow_link"/>
    	<origin xyz="-0.005 0 -0.05" rpy="0 0 0"/>
       	<limit lower="-1.57" upper="1.57" effort="10" velocity="3"/>
        <axis xyz="0 1 0"/>
	</joint>
	<!--
	<joint name="right_elbow_joint" type="continuous">
        <parent link="right_upper_arm_link"/>
        <child link="right_elbow_link"/>
        <origin xyz="-0.005 0 -0.05" rpy="0 0 0"/>
        <axis xyz="0 0 1"/>
        <dynamics damping="0.7"/>
    </joint>
	-->




 	<joint name="left_lower_arm_joint" type="fixed">
    	<parent link="left_elbow_link"/>
    	<child link="left_lower_arm_link"/>
    	<origin xyz="0 0 -0.08" rpy="0 0 0"/>
	</joint>

 	<joint name="right_lower_arm_joint" type="fixed">
    	<parent link="right_elbow_link"/>
    	<child link="right_lower_arm_link"/>
    	<origin xyz="0 0 -0.08" rpy="0 0 0"/>
	</joint>

 	<joint name="left_wrist_joint" type="revolute">
    	<parent link="left_lower_arm_link"/>
    	<child link="left_wrist_link"/>
    	<origin xyz="0 0 -0.05" rpy="0 0 0"/>
       	<limit lower="-1.57" upper="1.57" effort="10" velocity="3"/>
        <axis xyz="1 0 0"/>
	</joint>

 	<joint name="right_wrist_joint" type="revolute">
    	<parent link="right_lower_arm_link"/>
    	<child link="right_wrist_link"/>
    	<origin xyz="0 0 -0.05" rpy="0 0 0"/>
       	<limit lower="-1.57" upper="1.57" effort="10" velocity="3"/>
        <axis xyz="1 0 0"/>
	</joint>



 	<joint name="left_hand_joint" type="fixed">
    	<parent link="left_wrist_link"/>
    	<child link="left_hand_link"/>
    	<origin xyz="0 0 -0.055" rpy="0 0 0"/>
	</joint>

 	<joint name="right_hand_joint" type="fixed">
    	<parent link="right_wrist_link"/>
    	<child link="right_hand_link"/>
    	<origin xyz="0 0 -0.055" rpy="0 0 0"/>
	</joint>


    <transmission name="tran1">
        <type>transmission_interface/SimpleTransmission</type>
        <joint name="head_pan_joint">
            <hardwareInterface>hardware_interface/EffortJointInterface</hardwareInterface>
        </joint>
        <actuator name="motor1">
            <hardwareInterface>hardware_interface/EffortJointInterface</hardwareInterface>
            <mechanicalReduction>1</mechanicalReduction>
        </actuator>
    </transmission>

    <transmission name="tran2">
        <type>transmission_interface/SimpleTransmission</type>
        <joint name="head_tilt_joint">
            <hardwareInterface>hardware_interface/EffortJointInterface</hardwareInterface>
        </joint>
        <actuator name="motor2">
            <hardwareInterface>hardware_interface/EffortJointInterface</hardwareInterface>
            <mechanicalReduction>1</mechanicalReduction>
        </actuator>
    </transmission>

    <transmission name="tran3">
        <type>transmission_interface/SimpleTransmission</type>
        <joint name="torso_joint">
            <hardwareInterface>hardware_interface/EffortJointInterface</hardwareInterface>
        </joint>
        <actuator name="motor3">
            <hardwareInterface>hardware_interface/EffortJointInterface</hardwareInterface>
            <mechanicalReduction>1</mechanicalReduction>
        </actuator>
    </transmission>

    	<transmission name="tran4">
        <type>transmission_interface/SimpleTransmission</type>
        <joint name="left_shoulder_forward_joint">
            <hardwareInterface>hardware_interface/EffortJointInterface</hardwareInterface>
        </joint>
        <actuator name="motor4">
            <hardwareInterface>hardware_interface/EffortJointInterface</hardwareInterface>
            <mechanicalReduction>1</mechanicalReduction>
        </actuator>
    </transmission>

    <transmission name="tran5">
        <type>transmission_interface/SimpleTransmission</type>
        <joint name="right_shoulder_forward_joint">
            <hardwareInterface>hardware_interface/EffortJointInterface</hardwareInterface>
        </joint>
        <actuator name="motor5">
            <hardwareInterface>hardware_interface/EffortJointInterface</hardwareInterface>
            <mechanicalReduction>1</mechanicalReduction>
        </actuator>
    </transmission>

    <transmission name="tran6">
        <type>transmission_interface/SimpleTransmission</type>
        <joint name="left_shoulder_up_joint">
            <hardwareInterface>hardware_interface/EffortJointInterface</hardwareInterface>
        </joint>
        <actuator name="motor6">
            <hardwareInterface>hardware_interface/EffortJointInterface</hardwareInterface>
            <mechanicalReduction>1</mechanicalReduction>
        </actuator>
    </transmission>

    <transmission name="tran7">
        <type>transmission_interface/SimpleTransmission</type>
        <joint name="right_shoulder_up_joint">
            <hardwareInterface>hardware_interface/EffortJointInterface</hardwareInterface>
        </joint>
        <actuator name="motor7">
            <hardwareInterface>hardware_interface/EffortJointInterface</hardwareInterface>
            <mechanicalReduction>1</mechanicalReduction>
        </actuator>
    </transmission>

    	<transmission name="tran8">
        <type>transmission_interface/SimpleTransmission</type>
        <joint name="left_elbow_joint">
            <hardwareInterface>hardware_interface/EffortJointInterface</hardwareInterface>
        </joint>
        <actuator name="motor8">
            <hardwareInterface>hardware_interface/EffortJointInterface</hardwareInterface>
            <mechanicalReduction>1</mechanicalReduction>
        </actuator>
    </transmission>


    <transmission name="tran9">
        <type>transmission_interface/SimpleTransmission</type>
        <joint name="right_elbow_joint">
            <hardwareInterface>hardware_interface/EffortJointInterface</hardwareInterface>
        </joint>
        <actuator name="motor9">
            <hardwareInterface>hardware_interface/EffortJointInterface</hardwareInterface>
            <mechanicalReduction>1</mechanicalReduction>
        </actuator>
    </transmission>

    	<transmission name="tran10">
        <type>transmission_interface/SimpleTransmission</type>
        <joint name="left_wrist_joint">
            <hardwareInterface>hardware_interface/EffortJointInterface</hardwareInterface>
        </joint>
        <actuator name="motor10">
            <hardwareInterface>hardware_interface/EffortJointInterface</hardwareInterface>
            <mechanicalReduction>1</mechanicalReduction>
        </actuator>
    </transmission>


    <transmission name="tran11">
        <type>transmission_interface/SimpleTransmission</type>
        <joint name="right_wrist_joint">
            <hardwareInterface>hardware_interface/EffortJointInterface</hardwareInterface>
        </joint>
        <actuator name="motor11">
            <hardwareInterface>hardware_interface/EffortJointInterface</hardwareInterface>
            <mechanicalReduction>1</mechanicalReduction>
        </actuator>
    </transmission>


 <gazebo>
        <plugin name="gazebo_ros_control" filename="libgazebo_ros_control.so">
            <robotNamespace>/pi_robot</robotNamespace>
            <robotSimType>gazebo_ros_control/DefaultRobotHWSim</robotSimType>
        </plugin>
    </gazebo>


	<!-- Materials -->
    <!-- base_link -->
    <gazebo reference="base_link">
        <material>Gazebo/Blue</material>
    </gazebo>

    <!-- Link2 -->
    <gazebo reference="base_laser">
        <mu1>0.2</mu1>
        <mu2>0.2</mu2>
        <material>Gazebo/Black</material>
    </gazebo>

        <!-- Link2 -->
    <gazebo reference="cpu_link">
        <mu1>0.2</mu1>
        <mu2>0.2</mu2>
        <material>Gazebo/Blue</material>
    </gazebo>

        <!-- Link2 -->
    <gazebo reference="upper_base_link">
        <mu1>0.2</mu1>
        <mu2>0.2</mu2>
        <material>Gazebo/SkyBlue</material>
    </gazebo>

        <!-- Link2 -->
    <gazebo reference="torso_link">
        <mu1>0.2</mu1>
        <mu2>0.2</mu2>
        <material>Gazebo/Yellow</material>
    </gazebo>

        <!-- Link2 -->
    <gazebo reference="head_pan_link">
        <mu1>0.2</mu1>
        <mu2>0.2</mu2>
        <material>Gazebo/Green</material>
    </gazebo>


    <!-- Link2 -->
    <gazebo reference="head_tilt_link">
        <mu1>0.2</mu1>
        <mu2>0.2</mu2>
        <material>Gazebo/Green</material>
    </gazebo>

        <!-- Link2 -->
    <gazebo reference="neck_link">
        <mu1>0.2</mu1>
        <mu2>0.2</mu2>
        <material>Gazebo/Green</material>
    </gazebo>

        <!-- Link2 -->
    <gazebo reference="head_link">
        <mu1>0.2</mu1>
        <mu2>0.2</mu2>
        <material>Gazebo/Grey</material>
    </gazebo>

        <!-- Link2 -->
    <gazebo reference="antenna_link">
        <mu1>0.2</mu1>
        <mu2>0.2</mu2>
        <material>Gazebo/Grey</material>
    </gazebo>

        <!-- Link2 -->
    <gazebo reference="left_shoulder_link">
        <mu1>0.2</mu1>
        <mu2>0.2</mu2>
        <material>Gazebo/Green</material>
    </gazebo>



    <!-- Link2 -->
    <gazebo reference="right_shoulder_link">
        <mu1>0.2</mu1>
        <mu2>0.2</mu2>
        <material>Gazebo/Green</material>
    </gazebo>

    <!-- Link2 -->
    <gazebo reference="left_shoulder_forward_link">
        <mu1>0.2</mu1>
        <mu2>0.2</mu2>
        <material>Gazebo/Blue</material>
    </gazebo>

    <!-- Link2 -->
    <gazebo reference="right_shoulder_forward_link">
        <mu1>0.2</mu1>
        <mu2>0.2</mu2>
        <material>Gazebo/Blue</material>
    </gazebo>



    <!-- Link2 -->
    <gazebo reference="left_shoulder_up_link">
        <mu1>0.2</mu1>
        <mu2>0.2</mu2>
        <material>Gazebo/SkyBlue</material>
    </gazebo>


    <!-- Link2 -->
    <gazebo reference="right_shoulder_up_link">
        <mu1>0.2</mu1>
        <mu2>0.2</mu2>
        <material>Gazebo/SkyBlue</material>
    </gazebo>


    <!-- Link2 -->
    <gazebo reference="left_upper_arm_link">
        <mu1>0.2</mu1>
        <mu2>0.2</mu2>
        <material>Gazebo/Grey</material>
    </gazebo>

    <!-- Link2 -->
    <gazebo reference="right_upper_arm_link">
        <mu1>0.2</mu1>
        <mu2>0.2</mu2>
        <material>Gazebo/Grey</material>
    </gazebo>

    <!-- Link2 -->
    <gazebo reference="left_elbow_link">
        <mu1>0.2</mu1>
        <mu2>0.2</mu2>
        <material>Gazebo/Blue</material>
    </gazebo>

    <!-- Link2 -->
    <gazebo reference="right_elbow_link">
        <mu1>0.2</mu1>
        <mu2>0.2</mu2>
        <material>Gazebo/Blue</material>
    </gazebo>

    <!-- Link2 -->
    <gazebo reference="left_lower_arm_link">
        <mu1>0.2</mu1>
        <mu2>0.2</mu2>
        <material>Gazebo/Grey</material>
    </gazebo>

    <!-- Link2 -->
    <gazebo reference="right_lower_arm_link">
        <mu1>0.2</mu1>
        <mu2>0.2</mu2>
        <material>Gazebo/Grey</material>
    </gazebo>

    <!-- Link2 -->
    <gazebo reference="left_wrist_link">
        <mu1>0.2</mu1>
        <mu2>0.2</mu2>
        <material>Gazebo/Blue</material>
    </gazebo>

    <!-- Link2 -->
    <gazebo reference="right_wrist_link">
        <mu1>0.2</mu1>
        <mu2>0.2</mu2>
        <material>Gazebo/Blue</material>
    </gazebo>

    <!-- Link2 -->
    <gazebo reference="left_hand_link">
        <mu1>0.2</mu1>
        <mu2>0.2</mu2>
        <material>Gazebo/Grey</material>
    </gazebo>

    <!-- Link2 -->
    <gazebo reference="right_hand_link">
        <mu1>0.2</mu1>
        <mu2>0.2</mu2>
        <material>Gazebo/Grey</material>
    </gazebo>


</robot>